Workbook

Sheet 00_Dashboard
A1: SLR Quellen-Workflow Dashboard
A3: Kennzahl | B3: Formel / Wert | D3: Arbeitsreihenfolge | E3: Ziel | F3: Ergebnis | G3: Excel-Blatt | H3: Status
A4: Identifizierte Kandidaten | B4: =COUNTA('02_Screening'!C2:C472) -> 223 | D4: 1 | E4: Alle identifizierten Treffer erfassen | F4: Kandidatenliste mit Herkunft | G4: 02_Screening | H4: done
A5: Eingeschlossen | B5: =COUNTIF('02_Screening'!L2:L472,"Include") -> 113 | D5: 2 | E5: Datenbank-/Snowballing-Suche dokumentieren | F5: Suchlog + Trefferzahlen | G5: 01_Search_Log | H5: done
A6: Ausgeschlossen | B6: =COUNTIF('02_Screening'!L2:L472,"Exclude") -> 72 | D6: 3 | E6: Titel/Abstract + Volltext screenen | F6: Include/Exclude/Background | G6: 02_Screening | H6: done
A7: Background / Kontext | B7: =COUNTIF('02_Screening'!L2:L472,"Background") -> 38 | D7: 4 | E7: Finale Primärstudien extrahieren | F7: vergleichbare Codierung | G7: 03_Extraction | H7: done
A8: Unklar / prüfen | B8: =COUNTIF('02_Screening'!L2:L472,"Unklar") + COUNTIF('02_Screening'!L2:L472,"Zu prüfen") -> 0 | D8: 5 | E8: Qualität bewerten | F8: Q1-Q8 + Score | G8: 04_Quality_Assessment | H8: done
A9: Volltext geprüft | B9: =COUNTIF('02_Screening'!K2:K472,"Ja") -> 89 | D9: 6 | E9: Je Dokument Slide 2 erstellen | F9: 1 Folie je Paper | G9: 06_Slide2_Template | H9: done
A10: Extraktionen angelegt | B10: =COUNTIF('03_Extraction'!D2:D493,"<>") -> 113 | D10: 7 | E10: Thematische Einordnung | F10: Synthese nach RQ | G10: 05_RQ_Synthesis | H10: done
A11: Qualitätsbewertungen angelegt | B11: =COUNTIF('04_Quality_Assessment'!B2:B478,"<>") -> 113 | D11: 8 | E11: Research Gap formulieren | F11: Überleitung Experiment | G11: 05_RQ_Synthesis | H11: done
A12: Durchschnitt Qualitätsscore | B12: =IFERROR(AVERAGEIF('04_Quality_Assessment'!B2:B478,"<>",'04_Quality_Assessment'!K2:K478),"") -> 7.0221239 | D12: 9 | E12: SLR-Kapitel aktualisieren | F12: Methodik + Ergebnisse | G12: Manuskript | H12: done
D13: 10 | E13: Hilfstools sauber dokumentieren | F13: nicht als Datenbanken aufführen | G13: 01_Search_Log / 02_Screening | H13: done

Sheet 00_ReadMe
A1: Dokumentation der Systematic Literature Review
A3: Diese Arbeitsmappe dokumentiert die im Rahmen der Masterarbeit durchgeführte Systematic Literature Review (SLR). Sie ergänzt die methodische Beschreibung im Haupttext und dient der Nachvollziehbarkeit der Literatursuche, Studienauswahl, Qualitätsbewertung, Datenextraktion und forschungsfragenorientierten Synthese.
A7: Übersicht der Tabellenblätter
A8: Tabellenblatt | B8: Inhalt | C8: Zweck
A9: 00_Dashboard | B9: Zusammenfassende Kennzahlen der SLR und Überblick über den abgeschlossenen Bearbeitungsstand. | C9: Kompakte Übersicht über Suchprozess, Studienauswahl, Qualitätsbewertung und Synthese.
A10: 00_ReadMe | B10: Erläuterung der Struktur, Begriffe und verwendeten Kodierungen der digitalen SLR-Dokumentation. | C10: Orientierung innerhalb der Arbeitsmappe und Abgrenzung der einzelnen Dokumentationsschritte.
A11: 01_Search_Log | B11: Dokumentation der systematischen Suchläufe sowie ergänzender Recherche-, Citation-Discovery- und Snowballing-Aktivitäten einschließlich Suchquelle, Suchstring, Trefferzahl und Sichtungsumfang. | C11: Nachvollziehbarkeit der Literaturidentifikation und des Umfangs der gesichteten Ergebnislisten.
A12: 02_Screening | B12: Dokumentation der identifizierten Publikationen und ihrer Einordnung als Include, Exclude oder Background einschließlich Screeninginformationen und Ausschlussgründen. | C12: Nachvollziehbarkeit der Studienauswahl und der Trennung zwischen Synthesekorpus und Hintergrundliteratur.
A13: 03_Extraction | B13: Standardisierte Extraktion der 113 eingeschlossenen Primärstudien entlang der SLR-Forschungsfragen. | C13: Vergleichbare Erfassung der für die Synthese relevanten Studienmerkmale, Methoden und Ergebnisse.
A14: 04_Quality_Assessment | B14: Qualitätsbewertung der 113 eingeschlossenen Primärstudien anhand von acht Kriterien. | C14: Einordnung der methodischen und berichtsbezogenen Qualität der berücksichtigten Evidenz.
A15: 05_RQ_Synthesis | B15: Forschungsfragenorientierte Evidenzeinträge mit Kernaussagen, Fundstellen und analytischer Zuordnung. | C15: Grundlage der quellenübergreifenden narrativen und deskriptiven Synthese.
A17: Hinweise zur Suchdokumentation
A18: Aspekt | B18: Dokumentation
A19: Systematische Suchquellen | B19: Die systematische Literatursuche wurde über IEEE Xplore, ACM Digital Library, SpringerLink und arXiv durchgeführt.
A20: Explorative und ergänzende Recherche | B20: Google Scholar, Litmaps, Elicit, SciSpace und Connected Papers wurden für die explorative Vorrecherche, Citation Discovery sowie das Backward und Forward Snowballing eingesetzt. Diese Werkzeuge wurden nicht als eigenständige systematische Datenbanken behandelt.
A21: Treffer_raw | B21: Gesamtzahl der von der jeweiligen Suchquelle für den dokumentierten Suchlauf angezeigten Treffer.
A22: Treffer_gesichtet | B22: Anzahl der Ergebnisse, die innerhalb der jeweiligen Ergebnisliste tatsächlich betrachtet wurden.
A23: Sichtungsumfang | B23: „vollständig“ bedeutet, dass die gesamte Ergebnisliste gesichtet wurde. Bei sehr großen Treffermengen kann eine dokumentierte, nach Relevanz sortierte Teilmenge gesichtet worden sein.
A24: Weiteres Screening | B24: Potenziell relevante Publikationen wurden anschließend in das mehrstufige Studienauswahlverfahren übernommen.
A26: Hinweise zum Screening
A27: Aspekt | B27: Dokumentation
A28: Vorgehen | B28: Das Screening erfolgte mehrstufig. Nach einer Prüfung von Titel, Abstract und Keywords wurden bei unklarer oder potenzieller Relevanz weitere Publikationsabschnitte berücksichtigt.
A29: Volltextprüfung | B29: Für eingeschlossene Studien wurden die für die jeweiligen Forschungsfragen relevanten Inhalte des Volltexts vertieft geprüft. Die Volltextprüfung ist nicht als lineare Lektüre jeder einzelnen Seite zu verstehen, sondern als gezielte Auswertung insbesondere der relevanten Abschnitte zu Methodik, Architektur, Planung, Validierung, Evaluation, Ergebnissen und Limitationen.
A30: Include | B30: Die Publikation ist Bestandteil des Synthesekorpus der SLR.
A31: Background | B31: Die Publikation dient der begrifflichen, theoretischen oder methodischen Einordnung, ist jedoch nicht Bestandteil des Primärstudienkorpus der Synthese.
A32: Exclude | B32: Die Publikation wurde nicht in das Synthesekorpus aufgenommen. Ausschlussgründe sind im Screening dokumentiert.
A34: Hinweise zur Datenextraktion und Synthese
A35: Aspekt | B35: Dokumentation
A36: Datenextraktion | B36: Die 113 eingeschlossenen Primärstudien wurden mithilfe einer standardisierten, an den SLR-Forschungsfragen ausgerichteten Extraktionsmatrix ausgewertet.
A37: Fehlende Angaben | B37: Nicht berichtete oder aus einer Publikation nicht eindeutig ableitbare Informationen wurden nicht durch eigene Annahmen ergänzt, sondern entsprechend gekennzeichnet.
A38: RQ-Synthese | B38: Eine Studie kann mehrere Syntheseeinträge aufweisen, wenn sie Evidenz zu unterschiedlichen Forschungsfragen oder thematischen Kategorien liefert.
A39: Fundstellen | B39: Quellenbezogene Kernaussagen wurden mit Fundstellen dokumentiert, um die Rückverfolgbarkeit der Synthese zu den jeweiligen Primärstudien zu gewährleisten.
A40: Analytische Einordnung | B40: Quellenbezogene Aussagen und eigene analytische Einordnungen wurden getrennt dokumentiert.
A42: Hinweise zur Qualitätsbewertung
A43: Aspekt | B43: Dokumentation
A44: Bewertungsumfang | B44: Alle 113 eingeschlossenen Primärstudien wurden anhand von acht Qualitätskriterien bewertet.
A45: Bewertungsskala | B45: Je Kriterium wurden 0 Punkte bei fehlender beziehungsweise nicht nachvollziehbarer Erfüllung, 0,5 Punkte bei teilweiser Erfüllung und 1 Punkt bei vollständiger Erfüllung vergeben.
A46: Verwendung | B46: Der Gesamtscore dient der Einordnung der methodischen und berichtsbezogenen Qualität. Die Qualitätsbewertung wurde nicht als automatisches Ausschlusskriterium verwendet.
A48: Abgrenzung der digitalen Dokumentation
A49: Aspekt | B49: Dokumentation
...

Sheet 01_Search_Log
A1: Search_ID | B1: Datum | C1: Quelle_Typ | D1: Datenbank_Quelle | E1: Suchstring_oder_Methode | F1: Suchblock | G1: Filter | H1: Treffer_raw | I1: Treffer_gesichtet | J1: Screening_Umfang | K1: Screening_Regel | L1: Exportiert | M1: Duplikate_entfernt | N1: Golden_Set_gefunden | O1: Status | P1: Notizen
A2: IEEE-01 | B2: 46156 | C2: Datenbank | D2: IEEE Xplore | E2: (("LLM agent" OR "language agent" OR "large language model agent") AND ("planning" OR "reasoning" OR "tool use" OR "autonomous agent")) | F2: LLM-Agenten / Planung / Reasoning / Tool Use | G2: 2022–2026 | H2: 126 | I2: 126 | J2: vollständig | K2: Vollständige Sichtung der Ergebnisliste | L2: 18 | M2: 0 | N2: Teilweise | O2: Fertig | P2: Conferences: 102; Journals: 16; Early Access Articles: 5. Titel-/Abstract-Screening noch durchführen.
A3: IEEE-02 | B3: 46156 | C3: Datenbank | D3: IEEE Xplore | E3: (("web agent" OR "web automation" OR "web navigation") AND ("large language model" OR "LLM" OR "language agent")) | F3: Webagenten / Webnavigation / Webautomation | G3: 2022–2026 | H3: 7 | I3: 7 | J3: vollständig | K3: Vollständige Sichtung der Ergebnisliste | L3: 2 | M3: 1 | N3: Teilweise | O3: Fertig | P3: Conferences: 6; Journals: 1. Prüfen, ob der Filter 2022–2026 tatsächlich angewendet wurde.
A4: IEEE-03 | B4: 46156 | C4: Datenbank | D4: IEEE Xplore | E4: (("LLM agent" OR "language agent" OR "web agent") AND ("replanning" OR "reflection" OR "verification" OR "validation" OR "feedback")) | F4: Replanning / Reflection / Verification / Validation / Feedback | G4: 2022–2026 | H4: 87 | I4: 87 | J4: vollständig | K4: Vollständige Sichtung der Ergebnisliste | L4: 7 | M4: 3 | N4: Teilweise | O4: Fertig | P4: Conferences: 68; Journals: 12; Early Access Articles: 4. Titel-/Abstract-Screening noch durchführen.
A5: IEEE-04 | B5: 46156 | C5: Datenbank | D5: IEEE Xplore | E5: (("LLM agent" OR "web agent") AND ("success rate" OR "benchmark" OR "token cost" OR "latency" OR "runtime" OR "efficiency")) | F5: Evaluation / Benchmarks / Tokenkosten / Laufzeit / Effizienz | G5: 2022–2026 | H5: 101 | I5: 101 | J5: vollständig | K5: Vollständige Sichtung der Ergebnisliste | L5: 7 | M5: 6 | N5: Teilweise | O5: Fertig | P5: Conferences: 80; Journals: 16; Magazines: 3; Early Access Articles: 2. Titel-/Abstract-Screening noch durchführen.
A6: ACM-01 | B6: 46156 | C6: Datenbank | D6: ACM Digital Library | E6: (("LLM agent" OR "language agent" OR "large language model agent") AND ("planning" OR "reasoning" OR "tool use" OR "autonomous agent")) | F6: LLM-Agenten / Planung / Reasoning / Tool Use | G6: 2022–2026; Englisch; Volltext verfügbar | H6: 819 | I6: 500 | J6: effort-bounded | K6: Nach Relevanz sortierte Ergebnisliste, erste 500 Treffer gesichtet | L6: 20 | M6: 0 | N6: Teilweise | O6: Fertig | P6: Allgemeine Suche zu LLM-Agenten, Planung, Reasoning und Tool Use. Titel-/Abstract-Screening durchführen. --> ersten 150 wurden angesehen
A7: ACM-02 | B7: 46156 | C7: Datenbank | D7: ACM Digital Library | E7: (("web agent" OR "web automation" OR "web navigation") AND ("large language model" OR "LLM" OR "language agent")) | F7: Webagenten / Webnavigation / Webautomation | G7: 2022–2026; Englisch; Volltext verfügbar | H7: 184 | I7: 184 | J7: vollständig | K7: Vollständige Sichtung der Ergebnisliste | L7: 14 | M7: 5 | N7: Teilweise | O7: Fertig | P7: Spezifische Suche zu Webagenten, Webnavigation und Webautomation. Titel-/Abstract-Screening durchführen.
A8: ACM-03 | B8: 46156 | C8: Datenbank | D8: ACM Digital Library | E8: (("LLM agent" OR "language agent" OR "web agent") AND ("replanning" OR "reflection" OR "verification" OR "validation" OR "feedback")) | F8: Replanning / Reflection / Verification / Validation / Feedback | G8: 2022–2026; Englisch; Volltext verfügbar | H8: 847 | I8: 500 | J8: effort-bounded | K8: Nach Relevanz sortierte Ergebnisliste, erste 500 Treffer gesichtet | L8: 11 | M8: 19 | N8: Teilweise | O8: Fertig | P8: Suche zu Replanning, Reflection, Verification, Validation und Feedback. Titel-/Abstract-Screening durchführen.
A9: ACM-04 | B9: 46156 | C9: Datenbank | D9: ACM Digital Library | E9: (("LLM agent" OR "web agent") AND ("success rate" OR "benchmark" OR "token cost" OR "latency" OR "runtime" OR "efficiency")) | F9: Evaluation / Benchmarks / Tokenkosten / Laufzeit / Effizienz | G9: 2022–2026; Englisch; Volltext verfügbar | H9: 772 | I9: 500 | J9: effort-bounded | K9: Nach Relevanz sortierte Ergebnisliste, erste 500 Treffer gesichtet | L9: 6 | M9: 21 | N9: Teilweise | O9: Fertig | P9: Suche zu Evaluation, Benchmarking und Effizienzmetriken. Titel-/Abstract-Screening durchführen.
A10: ARXIV-01 | B10: 46156 | C10: Preprint | D10: arXiv | E10: (("LLM agent" OR "language agent" OR "large language model agent") AND ("planning" OR "reasoning" OR "tool use" OR "autonomous agent")) | F10: LLM-Agenten / Planung / Reasoning / Tool Use | G10: 2022–2026; Englisch; Preprints erlaubt | H10: 1754 | I10: 500 | J10: effort-bounded | K10: Nach Relevanz sortierte Ergebnisliste, erste 500 Treffer gesichtet | L10: 49 | M10: 25 | N10: Teilweise | O10: Fertig | P10: Allgemeine arXiv-Suche zu LLM-Agenten, Planung, Reasoning und Tool Use. Titel-/Abstract-Screening durchführen
A11: ARXIV-02 | B11: 46156 | C11: Preprint | D11: arXiv | E11: (("web agent" OR "web automation" OR "web navigation") AND ("large language model" OR "LLM" OR "language agent")) | F11: Webagenten / Webnavigation / Webautomation | G11: 2022–2026; Englisch; Preprints erlaubt | H11: 221 | I11: 221 | J11: vollständig | K11: Vollständige Sichtung der Ergebnisliste | L11: 14 | M11: 37 | N11: Teilweise | O11: Fertig | P11: Spezifische arXiv-Suche zu Webagenten, Webnavigation und Webautomation. Titel-/Abstract-Screening durchführen.
A12: ARXIV-03 | B12: 46156 | C12: Preprint | D12: arXiv | E12: (("LLM agent" OR "language agent" OR "web agent") AND ("replanning" OR "reflection" OR "verification" OR "validation" OR "feedback")) | F12: Replanning / Reflection / Verification / Validation / Feedback | G12: 2022–2026; Englisch; Preprints erlaubt | H12: 1229 | I12: 500 | J12: effort-bounded | K12: Nach Relevanz sortierte Ergebnisliste, erste 500 Treffer gesichtet | L12: 15 | M12: 41 | N12: Teilweise | O12: Fertig | P12: arXiv-Suche zu Replanning, Reflection, Verification, Validation und Feedback. Titel-/Abstract-Screening durchführen.
A13: ARXIV-04 | B13: 46156 | C13: Preprint | D13: arXiv | E13: (("LLM agent" OR "web agent") AND ("success rate" OR "benchmark" OR "token cost" OR "latency" OR "runtime" OR "efficiency")) | F13: Evaluation / Benchmarks / Tokenkosten / Laufzeit / Effizienz | G13: 2022–2026; Englisch; Preprints erlaubt | H13: 1864 | I13: 500 | J13: effort-bounded | K13: Nach Relevanz sortierte Ergebnisliste, erste 500 Treffer gesichtet | L13: 6 | M13: 62 | N13: Teilweise | O13: Fertig | P13: arXiv-Suche zu Evaluation, Benchmarks, Tokenkosten, Laufzeit und Effizienzmetriken. Titel-/Abstract-Screening durchführen.
... A17: SPRINGER-04 | B17: 46156 | C17: Datenbank | D17: Springer Nature Link / SpringerLink | E17: (("LLM agent" OR "web agent") AND ("success rate" OR "benchmark" OR "token cost" OR "latency" OR "runtime" OR "efficiency")) | F17: Evaluation / Benchmarks / Tokenkosten / Laufzeit / Effizienz | G17: 2022–2026; Englisch; Advanced Search; Keywords/All fields; Articles/Conference Papers/Chapters prüfen | H17: 451 | I17: 451 | J17: vollständig | K17: Vollständige Sichtung der Ergebnisliste | L17: 3 | M17: 6 | N17: Teilweise | O17: Fertig | P17: Suche zu Evaluation, Benchmarks, Tokenkosten, Laufzeit und Effizienzmetriken. Relevante/unklare Treffer in Screening übernehmen.
A18: CD-SB-01 | B18: 46156 | C18: Snowballing / Citation Discovery | D18: Litmaps / ResearchRabbit / Connected Papers | E18: Seed-basierte Citation Discovery ausgehend von relevanten Ausgangspaper(n); Forward-/Backward-Beziehungen und thematisch/zitationale Nähe geprüft | F18: Snowballing / Citation Discovery | G18: kein Datenbanktreffer; gleiche Ein-/Ausschlusskriterien wie übrige Kandidaten; genaue Tool-Herkunft einzelner Kandidaten nicht vollständig rekonstruierbar | H18: >1000 | I18: 200 | J18: effort-bounded | K18: nach Relevanz sortierte in den verschiedenen Quellen | L18: 7 | M18: 2 | N18: Teilweise | O18: Fertig | P18: Unterstützende Citation-Discovery- und Snowballing-Recherche über Google Scholar, Litmaps, Elicit, SciSpace und Connected Papers, überwiegend über Litmaps. Die Werkzeuge dienten der Identifikation verwandter sowie zitierter und zitierender Arbeiten und wurden nicht als eigenständige systematische Datenbanken behandelt. Alle identifizierten Publikationen wurden separat anhand derselben Ein- und Ausschlusskriterien geprüft. Im Rahmen dieser ergänzenden Recherche wurden unter anderem WebArena und BrowserGym berücksichtigt. Über dort referenzierte Projekt- beziehungsweise GitHub-Seiten wurde anschließend WebArena Verified identifiziert und als potenziell relevante Quelle separat geprüft.
A19: COT-01 | B19: 46156 | C19: Explorative Vorrecherche / Background | D19: CoT-/Reasoning-Literatur | E19: Gezielte ergänzende Recherche zu Chain-of-Thought, Reasoning und Prompting als theoretischer Hintergrund | F19: CoT / Reasoning / Planning Background | G19: keine Datenbanksuche; unterstützende Literatur; nur bei direktem Bezug zu Agenten, Planung oder Replanning als SLR-Kandidat berücksichtigt | H19: >200 | I19: 200 | J19: effort-bounded | K19: nach Relevanz sortierte in den verschiedenen Quellen | L19: 9 | N19: Teilweise | O19: Fertig | P19: CoT-/Reasoning-Quellen wurden vor allem zur theoretischen Einordnung von Reasoning, Chain-of-Thought und Planung genutzt. Sie werden nicht als Primärstudien der SLR behandelt, sofern kein direkter Bezug zu LLM-Agenten, Webagenten, Tool Use, Planungshorizonten oder Replanning besteht.

Sheet Übersicht der Extraktion
A3: Zeilenbeschriftungen | B3: Anzahl von Search_ID
A4: Background | B4: 38
A5: Exclude | B5: 72
A6: Include | B6: 113
A7: Gesamtergebnis | B7: 223
A15: Zeilenbeschriftungen | B15: Anzahl von Search_ID
A16: ACM-01 | B16: 20
A17: ACM-02 | B17: 14
A18: ACM-03 | B18: 11
A19: ACM-04 | B19: 6
A20: ARXIV-01 | B20: 49
A21: ARXIV-02 | B21: 14
A22: ARXIV-03 | B22: 15
A23: ARXIV-04 | B23: 6
A24: CD-SB-01 | B24: 7
A25: COT explizit | B25: 1
A26: COT-01 | B26: 8
A27: IEEE-01 | B27: 18
... A35: Gesamtergebnis | B35: 223

Sheet 02_Screening
A1: Candidate_ID | B1: Study_ID | C1: Titel | D1: Autor_Jahr | E1: Jahr | F1: Venue/Quelle | G1: DOI/URL | H1: Publikationstyp | I1: Herkunft | J1: Search_ID | K1: Volltext_geprüft | L1: Entscheidung | M1: Ausschlussgrund | N1: Relevanz_RQ | O1: Seed_Paper | P1: Snowballing_Typ | Q1: Duplikat_von | R1: Notizen | S1: Hilfstool_Hinweis | T1: Methodische_Einordnung | U1: Recherchetool_Typ
A2: C001 | B2: S001 | C2: Plan-and-Act: Improving Planning of Agents for Long-Horizon Tasks | D2: Erdogan et al. | E2: 2025 | F2: arXiv | G2: https://arxiv.org/abs/2503.09572 | H2: Preprint | I2: Datenbank / Preprint | J2: ARXIV-01 | K2: Ja | L2: Include | N2: RQ2; RQ3; RQ4; RQ5; Gap | T2: wissenschaftliche Datenbank
A3: C002 | B3: S002 | C3: Why Reasoning Fails to Plan: A Planning-Centric Analysis of Long-Horizon Decision Making in LLM Agents | D3: Wang et al. | E3: 2026 | F3: arXiv | G3: arXiv:2601.22311v1; https://arxiv.org/abs/2601.22311 | H3: Preprint | I3: Datenbank | J3: ARXIV-01 | K3: Ja | L3: Include | N3: RQ3; RQ4; RQ5; Gap | O3: Nein | T3: wissenschaftliche Datenbank
A4: C003 | B4: S003 | C4: Revealing the Barriers of Language Agents in Planning | D4: Xie et al. | E4: 2025 | F4: NAACL-HLT 2025, Volume 1: Long Papers | G4: https://doi.org/10.18653/v1/2025.naacl-long.93; https://aclanthology.org/2025.naacl-long.93/ | H4: Conference Paper | I4: Datenbank | J4: ARXIV-01 | K4: Ja | L4: Include | N4: RQ2; RQ3; RQ5; Gap; Methodik | O4: Nein | R4: - Sehr relevant für Planungsgrenzen von LLM-/Language-Agenten, insbesondere Long-Horizon-Planung. - Analysiert Planning-Module, Constraints, Questions sowie episodic und parametric memory updating. - Nutzt Permutation Feature Importance zur Diagnose: Constraints werden zu wenig berücksichtigt, Question-Einfluss sinkt mit Planungshorizont. - Evaluiert auf BlocksWorld und TravelPlanner; Forschungslücke: keine direkte Webagentenstudie, aber stark übertragbar auf Webagenten-Planung und Evaluationsmetriken. | T4: wissenschaftliche Datenbank
A5: C004 | B5: S004 | C5: TREE-PLANNER: Efficient Close-loop Task Planning with Large Language Models | D5: Hu et al. | E5: 2024 | F5: ICLR 2024 / OpenReview | G5: https://openreview.net/forum?id=Glcsog6zOe; arXiv:2310.08582; https://arxiv.org/abs/2310.08582 | H5: Conference Paper | I5: Datenbank | J5: ARXIV-03 | K5: Ja | L5: Include | N5: RQ1; RQ2; RQ3; RQ4; RQ5; Gap | O5: Nein | R5: - Sehr relevant für closed-loop LLM-Planung, Replanning und Effizienzmetriken. - Architektur: Plan Sampling, Action Tree Construction und Grounded Deciding als hybrider vorgeplanter Suchraum mit online Auswahl. - Validierung/Replanning erfolgt environment-grounded über Beobachtungen, Fehlermeldungen, Backtracking und Neuauswahl am letzten gültigen Fork. - Evaluiert auf VirtualHome mit EXEC, Success Rate, GCR, Tokenkosten/$COST und NO.EC; Forschungslücke: keine direkte Webagenten-Evaluation und keine systematische Variation von Validierungsintervallen. | T5: wissenschaftliche Datenbank
A6: C005 | B6: S005 | C6: LLMPC: Large Language Model Predictive Control | D6: Maher | E6: 2025 | F6: arXiv | G6: arXiv:2501.02486v2; https://arxiv.org/abs/2501.02486 | H6: Preprint | I6: Datenbank | J6: ARXIV-01 | K6: Ja | L6: Include | N6: RQ3; RQ4; RQ5; Gap | O6: Nein | R6: - Hoch relevant für LLM-Planung als receding-horizon / MPC-artiger Zyklus mit Plan-Sampling, externer Bewertung, Teil-Ausführung und Replanning. - Architektur/Methode: LLM generiert K Kandidatenpläne, externe Kosten-/Constraint-Funktion wählt den besten Plan, danach iterative Verbesserung mit aktualisiertem Feedback. - Validierung erfolgt constraint-based durch externe Evaluation unerfüllter Constraints, insbesondere in Trip- und Meeting-Planning-Aufgaben. - Evaluiert mit Objective Ratio und Success Rate; Forschungslücke: keine systematische Messung von Tokenkosten, Laufzeit, Replan-Anzahl oder Validierungsintervallen. | T6: wissenschaftliche Datenbank
A7: C006 | B7: S006 | C7: Token-Budget-Aware LLM Reasoning | D7: Han et al. | E7: 2025 | F7: arXiv | G7: arXiv:2412.18547v4; https://arxiv.org/abs/2412.18547 | H7: Preprint | I7: Datenbank | J7: ARXIV-01 | K7: Ja | L7: Background | N7: RQ5; Gap; Methodik | O7: Nein | R7: - Background-Quelle zu CoT, Reasoning-Budget und Tokenkosten; nicht direkt zu Webagenten oder agentischer Planung. - Methode: TALE-EP schätzt ein Reasoning-Tokenbudget und setzt es im Prompt; TALE-PT internalisiert Budgetbewusstsein per SFT/DPO. - Relevant für Effizienzmetriken, Accuracy-Cost-Trade-off und die Frage, ob längeres Reasoning immer nötig ist. - Keine Laufzeitvalidierung, kein Replanning, keine interaktive Umgebung; eher nützlich für Ausblick und Effizienz-Diskussion. | S7: Priorität: C-Background; reduzierte Extraction ausreichend; Snowballing optional zu CoT/Reasoning-Kosten
A8: C007 | B8: S007 | C8: Think-on-Graph: Deep and Responsible Reasoning of Large Language Model on Knowledge Graph | D8: Sun et al. (2024) | E8: 2024 | F8: ICLR 2024 / OpenReview | G8: https://openreview.net/forum?id=nnVO1PvbTv; arXiv:2307.07697; https://arxiv.org/abs/2307.07697 | H8: Conference Paper | I8: Datenbank | J8: ARXIV-04 | K8: Ja | L8: Include | N8: RQ2; RQ3; RQ4; RQ5; Gap; Methodik | O8: Nein | R8: - Relevant als B-Supporting-Include für agentische Architektur, strukturierte Exploration und tiefe Multi-Hop-Reasoning-Prozesse, aber keine direkte Webagentenstudie. - Methode: LLM⊗KG-Paradigma mit LLM-Agent, Knowledge-Graph-Exploration, Beam Search, Search/Prune-Schritten und iterativer Reasoning-Sufficiency-Prüfung. - Validierung/Fehlerbehandlung: explizite reasoning paths ermöglichen Traceability und Knowledge Correctability; LLM entscheidet nach Iterationen, ob genug Information vorhanden ist. - Evaluation auf 9 KGQA/Open-Domain/Fact-Checking-Datasets mit Hits@1; untersucht Suchbreite/-tiefe, Pruning-Tools und LLM-Call-Kosten; Forschungslücke: Übertragbarkeit auf Webagenten, Browserumgebungen und Replanning während realer Handlungsausführung bleibt offen.
A9: C008 | B9: S008 | C9: Plan-on-Graph: Self-Correcting Adaptive Planning of Large Language Model on Knowledge Graphs | D9: Chen et al. (2024) | E9: 2024 | F9: NeurIPS 2024 / arXiv | G9: arXiv:2410.23875; https://arxiv.org/abs/2410.23875; https://github.com/liyichen-cly/PoG | H9: Conference Paper | I9: Datenbank | J9: ARXIV-04 | K9: Ja | L9: Include | N9: RQ2; RQ3; RQ4; RQ5; Gap; Methodik | O9: Nein | R9: - Relevant als starkes B-Supporting-Include für adaptive Planung, Self-Correction, Reflection und Memory, aber keine direkte Webagentenstudie. - Methode: Plan-on-Graph mit Task Decomposition, adaptiver Path Exploration, Memory Updating und Evaluation/Reflection auf Knowledge Graphs. - Validierung/Replanning: Reflection prüft, ob Informationen ausreichen oder ob fehlerhafte Reasoning Paths per Backtracking korrigiert werden müssen. - Evaluation auf CWQ, WebQSP und GrailQA mit Hits@1 sowie LLM Calls, Input/Output Tokens, Total Tokens und Laufzeit; Forschungslücke: Übertragbarkeit auf Webagenten, Browserinteraktion und reale Tool-/UI-Ausführung bleibt offen.
A10: C009 | B10: S009 | C10: LATCH: latency-bounded latent lookahead for constraint-safe web agents | D10: Li et al. (2026) | E10: 2026 | F10: Research Square | G10: https://doi.org/10.21203/rs.3.rs-8912469/v1 | H10: Preprint | I10: Preprint-Suchquelle | J10: ARXIV-02 | K10: Ja | L10: Include | N10: RQ2; RQ3; RQ4; RQ5; Gap; Methodik | O10: Nein | R10: - Sehr relevantes A-Core-Include zu LLM-basierten Webagenten, Lookahead-Planung, Constraint-Sicherheit und Effizienz unter Interaktionsbudgets. - Architektur: Action Proposal Module, Encoder, Hybrid SSM+Attention Dynamics, Typed Entity Memory, kalibrierter Critic und Beam-/Horizon-basierter Planner. - Planung/Validierung: simulate-then-select in latent space, schema-valide Kandidaten, short-horizon rollouts, constraint propagation und shared validators zur Reduktion ungültiger Aktionen. - Evaluation auf WebShop, Mind2Web und WebArena mit TSR, CVR, IAR, Tokens, latent evaluations, wall-time und selection error; Forschungslücke: Preprint noch nicht peer-reviewed und Fokus auf textbasierte DOM-/Tool-Interfaces, nicht multimodale Webagenten. | S10: aus vorhandenen Notizen/PDF geprüft; Priorität: A-Core-Include; Preprint-Status beachten; Snowballing prüfen zu WebArena, Mind2Web, WebShop, ReAct, Tree-of-Thoughts, world models und BrowserGym | T10: Preprint-Suchquelle
A11: C010 | B11: S010 | C11: WebOperator: Action-Aware Tree Search for Autonomous Agents in Web Environment | D11: Dihan et al. (2025) | E11: 2025 | F11: arXiv | G11: arXiv:2512.12692v1; https://arxiv.org/abs/2512.12692; https://kagnlp.github.io/WebOperator/ | H11: Preprint | I11: Datenbank | J11: ARXIV-02 | K11: Ja | L11: Include | N11: RQ1; RQ2; RQ3; RQ4; RQ5; Gap; Methodik | O11: Nein | R11: - Sehr relevantes A-Core-Include zu LLM-basierten Webagenten, Tree Search, Backtracking und sicherer Webautomation. - Architektur: action-aware Best-First Search mit dynamischem Action Space, Action Validation, Context Variation, Action Merging, Reward Model und Search Tree. - Validierung/Replanning: speculative Backtracking mit Snapshot-Validierung, checkpoint-based state jumping sowie pre-/post-execution heuristics für destructive actions. - Evaluation auf WebArena und WebVoyager; berichtet Success Rate, Suchbudget, Backtracking-Verteilung, Ablationen und generierte Aktionen; Forschungslücke: Umgang mit hochdynamischen Websites, Destructive-Action-Heuristiken und Reward-Model-Abhängigkeit bleibt offen. | T11: aus vorhandenen Notizen/PDF geprüft; Priorität: A-Core-Include; Snowballing prüfen zu LM-TS, LATS, WebPilot, Branch-n-Browse, WebRollback, WebGuard, InferAct, WebArena und WebVoyager | U11: Preprint-Suchquelle
A12: C011 | B12: S011 | C12: PATHWAYS: Evaluating Investigation and Context Discovery in AI Web Agents | D12: Arman et al. (2026) | E12: 2026 | F12: arXiv | G12: arXiv:2602.05354v2; https://arxiv.org/abs/2602.05354 | H12: Benchmark Paper / Preprint | J12: ARXIV-04 | K12: Ja | L12: Include | N12: RQ1; RQ3; RQ4; RQ5; Gap; Methodik | O12: Nein | R12: - Sehr relevantes A-Core-Include / Benchmark Paper zu AI-Webagenten, investigativer Kompetenz, verstecktem Kontext und evidenzbasierter Entscheidung. - Methode: PATHWAYS benchmark mit 250 mehrstufigen Entscheidungsaufgaben in Shopping-Admin- und Reddit-Moderation-Domänen auf WebArena-Basis. - Validierung/Fehleranalyse: misst Navigation–Discovery Gap, Surface Contradiction, Investigative Hallucination, Evidence Integration und Entscheidung unter Informationsasymmetrie. - Evaluation mit Investigation Accuracy, Reasoning Accuracy, Decision Accuracy, Proven Success Rate, Investigative Efficiency und Evidence Quality; Forschungslücke: Agenten brauchen explizite Mechanismen für Unsicherheit, Informationssuffizienz, Evidenzsuche und Judgement Override.
A13: C012 | B13: S012 | C13: Limits of Self-Correction in LLMs: An Information-Theoretic Analysis of Correlated Errors | D13: Brilliant (2026) | E13: 2026 | F13: Preprints.org | G13: https://doi.org/10.20944/preprints202601.0892.v1 | H13: Preprint | I13: Preprint-Suchquelle | J13: ARXIV-01 | K13: Ja | L13: Background | N13: RQ4; Gap; Methodik | O13: Nein | R13: - Background-Quelle zu Grenzen von Self-Correction, Self-Evaluation und korrelierten Fehlern bei LLMs; keine direkte Webagentenstudie. - Methode: theoretisch-informationstheoretische Analyse von Generator-/Evaluator-Fehlerkopplung sowie Vorschlag von context-separated external selection. - Relevant für Validierungsdiskussion: erklärt, warum reine Self-Critique/Reflection ohne externe Signale fehlschlagen oder falsches Vertrauen verstärken kann. - Keine Evaluation auf Webagenten-Benchmarks, keine Planungsausführung, kein Replanning in interaktiven Umgebungen; daher nur optional für Ausblick/Grenzen von Reflection nutzen.
A14: C013 | B14: S013 | C14: Reasoning Models Struggle to Control their Chains of Thought | D14: Yueh-Han et al. (2026) | E14: 2026 | F14: arXiv | G14: arXiv:2603.05706v1; https://arxiv.org/abs/2603.05706 | H14: Preprint | I14: Preprint-Suchquelle | J14: ARXIV-01 | K14: Ja | L14: Background | N14: RQ4; RQ5; Gap; Methodik | O14: Nein | R14: - Background-Quelle zu CoT-Monitoring, CoT-Controllability und Grenzen kontrollierbarer Reasoning-Spuren; keine direkte Webagentenstudie. - Methode: CoT-Control Evaluation Suite mit 14.076 Instanzen aus QA- und agentischen Benchmarks; misst, ob Modelle ihr CoT gezielt steuern können. - Relevant für Validierung: zeigt, dass Reasoning-Modelle ihre CoT meist deutlich schlechter kontrollieren als finale Outputs; längeres Reasoning, höhere Schwierigkeit und mehr Reasoning-Effort reduzieren Controllability. - Keine Webnavigation, keine Browserumgebung, kein Replanning und keine Webagenten-spezifischen Effizienzmetriken; daher vor allem für Diskussion zu CoT, Monitoring, Prompting und Validierungsgrenzen nutzbar.
A15: C014 | B15: S014 | C15: Why Language Models Hallucinate | D15: Kalai et al. (2025) | E15: 2025 | F15: arXiv | G15: arXiv:2509.04664v1; https://arxiv.org/abs/2509.04664 | H15: Preprint | I15: Preprint-Suchquelle | J15: ARXIV-03 | K15: Ja | L15: Background | N15: RQ4; RQ5; Gap; Methodik | O15: Nein | R15: - Background-Quelle zu Halluzinationen, Unsicherheit und Evaluationsanreizen bei Sprachmodellen; keine direkte Webagentenstudie. - Methode: theoretische Analyse von Halluzinationen als generative Fehler bzw. Is-It-Valid-Klassifikationsproblem in Pretraining und Post-training. - Relevant für Validierung/Evaluation: zeigt, dass binäre Benchmarks Guessing belohnen und Unsicherheit/IDK bestrafen, wodurch plausible falsche Aussagen bestehen bleiben. - Keine Agentenarchitektur, keine Webnavigation, kein Replanning und keine Webagentenmetriken; nutzbar für Diskussion zu Fehlerquellen, Unsicherheitsmodellierung und Evaluationsdesign.
A16: C015 | B16: S015 | C16: When Chain of Thought is Necessary, Language Models Struggle to Evade Monitors | D16: Emmons et al. (2025) | E16: 2025 | F16: arXiv | G16: arXiv:2507.05246v1; https://arxiv.org/abs/2507.05246 | H16: Preprint | I16: Preprint-Suchquelle | J16: ARXIV-01 | K16: Ja | L16: Background | N16: RQ3; RQ4; RQ5; Gap; Methodik | O16: Nein | R16: - Background-Quelle zu CoT-Monitoring, Monitorability und Grenzen von CoT-Evasion; keine direkte Webagentenstudie. - Methode: konzeptueller Rahmen mit CoT-as-rationalization vs. CoT-as-computation sowie Stress-Tests gegen CoT-Monitore. - Relevant für Validierung: zeigt, dass CoT bei schwierigen Aufgaben eher notwendig und damit monitorierbar wird, während einfache Aufgaben unfaithful rationalizations erlauben. - Evaluation mit GPQA-, Stealth- und Math-Proxy-Settings; untersucht Task Success, Monitor Recall, False Positive Rate und Evasion-Performance; Forschungslücke: keine Webnavigation, keine Browserumgebung und keine direkten Replanning-/Webagentenmetriken.
A17: C016 | B17: S016 | C17: Beyond the Imitation Game: Quantifying and extrapolating the capabilities of language models | D17: Srivastava et al. (2023) | E17: 2023 | F17: arXiv | G17: arXiv:2206.04615v3; https://arxiv.org/abs/2206.04615 | H17: Benchmark Paper / Preprint | I17: Preprint-Suchquelle | J17: ARXIV-03 | K17: Ja | L17: Exclude | M17: Zu allgemeines LLM-Benchmarking; keine direkte Webagentenstudie, keine Agentenarchitektur, keine Webnavigation, keine Planung/Replanning-Ausführung und keine Webagenten-spezifischen Evaluationsmetriken. | N17: Methodik | O17: Nein | R17: - Großes allgemeines Benchmark-Paper zu Sprachmodellfähigkeiten und Skalierung, aber ohne direkten Bezug zu Webagenten. - BIG-bench untersucht diverse Sprachmodellaufgaben, jedoch keine Browserinteraktion, Webautomation oder agentische Trajektorien. - Für die SLR höchstens indirekt als Kontext zu Benchmarking, Kalibrierung und Multi-Step-Aufgaben nutzbar. - Aufgrund fehlender direkter Relevanz für Webagenten, Planung, Replanning und prozessbezogene Webagentenmetriken nicht weiter extrahieren.
A18: C017 | B18: S017 | C18: WebATLAS: An LLM Agent with Experience-Driven Memory and Action Simulation | D18: Cheng et al. (2025) | E18: 2025 | F18: NeurIPS 2025 Workshop LAW 2025 / arXiv | G18: arXiv:2510.22732v2; https://arxiv.org/abs/2510.22732 | H18: Workshop Paper / Preprint | I18: Preprint-Suchquelle | J18: ARXIV-01 | K18: Ja | L18: Include | N18: RQ1; RQ2; RQ3; RQ4; RQ5; Gap; Methodik | O18: Nein | R18: - Sehr relevantes A-Core-Include zu LLM-basierten Webagenten, Long-Horizon-Webnavigation, Memory, Planning, Look-ahead Simulation und dynamischem Replanning. - Architektur: modularer Planner-Actor-Critic-Agent mit Working Memory, Cognitive Map und Semantic Memory; Figure 1 zeigt den Flow aus Observation/Abstractor, Planner, Actor, Critic, Memory Construction und LAS. - Planung/Validierung/Replanning: Actor generiert Kandidaten, Critic simuliert zukünftige Zustände über Cognitive Map, bewertet Risiko/Recoverability/Plan-Konsistenz und löst Replanning bei Abweichung zwischen erwarteter und beobachteter Observation aus. - Evaluation auf WebArena-Lite mit 63,0 % Success Rate gegenüber 53,9 % vorherigem SOTA; Forschungslücke: Tokenkosten, Laufzeit, Replan-Anzahl, Fehlerpositionen und Validierungsintervalle werden kaum systematisch gemessen. | T18: aus vorhandenen Notizen/PDF geprüft; Priorität: A-Core-Include; Snowballing prüfen zu WebArena-Lite, AgentOccam, Plan-and-Act, WebRL, WebPilot, AWM, ReAct, Reflexion, Tree of Thoughts, World Models und BrowserGym
A19: C018 | B19: S018 | C19: WebAgent-R1: Training Web Agents via End-to-End Multi-Turn Reinforcement Learning | D19: Wei et al. (2025) | E19: 2025 | F19: EMNLP 2025 / ACL Anthology | G19: https://aclanthology.org/2025.emnlp-main.401/; arXiv:2505.16421; https://arxiv.org/abs/2505.16421; https://github.com/weizhepei/WebAgent-R1 | H19: Conference Paper | I19: Datenbank | J19: ARXIV-02 | K19: Ja | L19: Include | N19: RQ1; RQ2; RQ3; RQ5; Gap; Methodik | O19: Nein | R19: - Sehr relevantes A-Core-Include zu LLM-basierten Webagenten, Multi-Turn-RL, Long-Horizon-Webtasks und Evaluation auf WebArena-Lite. - Methode: Behavior Cloning als Warm-up, danach end-to-end Multi-Turn Reinforcement Learning mit M-GRPO, Dynamic Context Compression und Parallel Trajectory Rollout. - Planung/Validierung: keine explizite Planrepräsentation und kein separates Replanning; Entscheidungsverhalten wird implizit über komplette Web-Trajektorien und binäre End-Rewards gelernt. - Evaluation auf WebArena-Lite und WebVoyager-OOD mit Success Rate, Trajectory Length und Number of Interactions; Forschungslücke: Tokenkosten, Laufzeit, Zwischenvalidierung, Replan-Anzahl und Fehlerpositionen werden nicht systematisch untersucht.
A20: C019 | B20: S019 | C20: ColorBrowserAgent: Complex Long-Horizon Browser Agent with Adaptive Knowledge Evolution | D20: Wang et al. (2026) | E20: 2026 | F20: arXiv / Preprint under review | G20: arXiv:2601.07262v2; https://arxiv.org/abs/2601.07262; https://github.com/MadeAgents/browser-agent.git | H20: Preprint | I20: Preprint-Suchquelle | J20: ARXIV-01 | K20: Ja | L20: Include | N20: RQ1; RQ2; RQ3; RQ4; RQ5; Gap; Methodik | O20: Nein | R20: - Sehr relevantes A-Core-Include zu Long-Horizon-Browseragenten, Site-Heterogenität, Decision Drift und stabilisierter Webautomation. - Architektur: ColorBrowserAgent mit Adaptor, Summarizer, Operator und Adaptive Knowledge Base; kombiniert Offline Knowledge Adaptation mit Online Execution Loop. - Validierung/Stabilisierung: Knowledge-Aligned Progressive Summarization komprimiert Interaktionshistorie, prüft geplante Aktionen gegen abgerufenes Expertenwissen und injiziert korrigierende Guidance bei Abweichungen. - Evaluation auf WebArena, WebChoreArena und industriellem Deployment mit Success Rate und User Satisfaction; Forschungslücke: Tokenkosten, Laufzeit, Validierungsfrequenz, Replan-Anzahl und explizite Drift-/Recovery-Metriken werden nicht systematisch gemessen.
A21: C020 | B21: S020 | C21: Agentic Test-Time Scaling for WebAgents | D21: Lee et al. (2026) | E21: 2026 | F21: arXiv | G21: arXiv:2602.12276v1; https://arxiv.org/abs/2602.12276 | H21: Preprint | I21: Preprint-Suchquelle | J21: ARXIV-02 | K21: Ja | L21: Include | N21: RQ2; RQ3; RQ4; RQ5; Gap; Methodik | O21: Nein | R21: - Sehr relevantes A-Core-Include zu agentischem Test-Time Scaling, adaptiver Validierung und Effizienzmetriken bei Long-Horizon-Webagenten. - Methode: CATTS nutzt per-step Candidate Sampling, semantisches Action-Clustering, Majority Vote, LLM-Arbiter und vote-derived uncertainty über Entropie bzw. Top-1/Top-2-Margin. - Validierung/Compute-Steuerung: zusätzliche Arbiter-Prüfung wird nur bei unsicheren, kontroversen Entscheidungsschritten eingesetzt; bei hohem Konsens reicht Majority Vote und zusätzliche Validierung kann sogar schaden. - Evaluation auf WebArena-Lite und GoBrowse mit Success Rate und Tokenverbrauch; Forschungslücke: kein globales Planning/Replanning-Modul, keine systematische Analyse von Fehlerpositionen, Recovery oder Validierungsintervallen über mehrere Schritte.
A22: C021 | B22: S021 | C22: SkillRL: Evolving Agents via Recursive Skill-Augmented Reinforcement Learning | D22: Xia et al. (2026) | E22: 2026 | F22: arXiv | G22: arXiv:2602.08234v1; https://arxiv.org/abs/2602.08234; https://github.com/aiming-lab/SkillRL | H22: Preprint | I22: Preprint-Suchquelle | J22: ARXIV-03 | K22: Ja | L22: Include | N22: RQ2; RQ3; RQ4; RQ5; Gap; Methodik | O22: Nein | R22: - Relevantes B-Supporting-Include als alternative Architekturklasse zu Memory- und RL-basierten LLM-Agenten; nicht direkt WebArena-/Browseragenten-zentriert, aber mit WebShop und Long-Horizon-Agentenbezug. - Methode: SkillRL destilliert erfolgreiche und fehlgeschlagene Trajektorien in eine hierarchische SKILLBANK mit General Skills und Task-Specific Skills, die während der Ausführung retrieved werden. - Planung/Fehlerbehandlung: Skills unterstützen mehrstufige Entscheidungsstrategien; Failed Trajectories werden in Failure Lessons überführt und die Skill Library wird während RL rekursiv weiterentwickelt. - Evaluation auf ALFWorld, WebShop und Search-Augmented-QA mit Success Rate, Score und Kontext-/Promptlänge; Forschungslücke: keine direkte WebArena-/BrowserGym-Evaluation, kein explizites Replanning-Modul und keine systematische Analyse von Laufzeit, Validierungsintervallen oder Fehlerpositionen.
A23: C022 | B23: S022 | C23: SkillEvo: An Experience Learning Framework with Reinforcement Learning for Skill Evolution | D23: Xu et al. (2026) | E23: 2026 | F23: ICLR 2026 / OpenReview | G23: https://openreview.net/forum?id=S1cIE9pe3k | H23: Conference Paper | I23: wissenschaftliche Datenbank | J23: ARXIV-03 | K23: Ja | L23: Include | N23: RQ1; RQ2; RQ3; RQ4; RQ5; Gap; Methodik | O23: Nein | R23: - Relevantes Include als alternative Skill-Evolution- und RL-Ansatzklasse für LLM-basierte Webagenten; direkter Bezug zu Long-Horizon-Webtasks und WebArena-Lite. - Methode: SkillEvo kombiniert WebGRPO mit RXERM für Reasoning-/Execution-Rewards, Dual-Uncertainty-Based Active Learning und SkillGenesis zur Umwandlung von Trajektorien in wiederverwendbare Skills. - Planung/Validierung: Skills werden in einem Skill Path Graph organisiert, wiederverwendet und zu Composite Skills weiterentwickelt; Validierung erfolgt über Execution Reward, Reasoning Reward, Format Reward und Skill-Verifikation, aber ohne klassisches Online-Replanning-Modul. - Evaluation auf WebArena-Lite mit Success Rate und Ablationen zu RXERM, Uncertainty Filtering und Skill Evolution; Forschungslücke: hohe Trainingskosten, Reward-Abhängigkeit, fragile Skill-Komposition sowie fehlende systematische Analyse von Tokenkosten, Laufzeit, Fehlerpositionen und Replanning-/Validierungsintervallen.
A24: C023 | B24: S023 | C24: Self-Guided Hierarchical Exploration for Generalist Foundation Model Web Agents | D24: Yang et al. (2025) | E24: 2025 | F24: NeurIPS 2025 | G24: https://yanqval.github.io/SAGE/ | H24: Conference Paper | I24: Datenbank | J24: ARXIV-02 | K24: Ja | L24: Include | N24: RQ1; RQ2; RQ3; RQ4; RQ5; Gap; Methodik | O24: Nein | R24: - Sehr relevantes A-Core-Include zu generalistischen Webagenten, Long-Horizon-Webtasks, hierarchischer Exploration und autonomer Skill-Akquisition. - Methode: SAGE kombiniert Pre-Exploration zum Aufbau einer Website-Strukturkarte, Top-Level Exploration mit selbstadaptivem Task-Curriculum und Low-Level Exploration mit MCTS, Multi-Action Policy, Outcome Evaluator und Step-DPO. - Planung/Validierung: MCTS unterstützt strukturierte Aktionssequenzsuche; ein gelernter Outcome Evaluator bewertet Erfolg/Misserfolg und Stepwise Learning nutzt Divergenzpunkte zwischen erfolgreichen und fehlgeschlagenen Trajektorien. - Evaluation auf WebVoyager und WebArena mit Success Rate, Ablationen, Schwierigkeit nach Task-Länge und Error Analysis; Forschungslücke: keine systematische Analyse von Tokenkosten, Laufzeit, Online-Replanning-Frequenz oder Validierungsintervallen während der Ausführung.
A25: C024 | B25: S024 | C25: A Survey on the Optimization of Large Language Model-based Agents | D25: Du et al. (2026) | E25: 2026 | F25: ACM Computing Surveys | G25: https://doi.org/10.1145/3789261; https://github.com/YoungDubbyDu/LLM-Agent-Optimization | H25: Survey | I25: wissenschaftliche Datenbank | J25: ACM-01 | K25: Teilweise | L25: Include | N25: RQ1; RQ2; RQ3; RQ4; RQ5; Gap; Methodik | O25: Nein | R25: - Sehr relevante zentrale Background-/Survey-Quelle zur Optimierung von LLM-basierten Agenten; keine einzelne Primärstudie zu Webagenten, aber stark für Taxonomie und theoretische Einordnung. - Methode/Struktur: kategorisiert Agentenoptimierung in parameter-driven Ansätze wie Fine-Tuning, RL, Hybrid Optimization sowie parameter-free Ansätze wie Experience-, Feedback-, Tool-, Retrieval- und Multi-Agent-basierte Optimierung. - Relevanz für Planung/Validierung: behandelt Trajectory Construction, Reward Function Design, Preference Alignment, Self-Reflection, External Feedback, Model-/Environment-based Evaluation und langfristige Agentenadaption. - Evaluation/Gap: fasst Frameworks, Datasets, Evaluation und Herausforderungen zusammen; besonders nützlich zur Begründung von Forschungslücken bei Long-Horizon Planning, Feedback-Design, Replanning, Effizienz und Evaluation von LLM-Agenten.
A26: C025 | B26: S025 | C26: Self-evolving Agents with reflective and memory-augmented abilities | D26: 梁学辰 et al. (2026) | E26: 2025 | F26: Anonymous submission / Preprint | G26: https://arxiv.org/abs/2409.00872, https://dl.acm.org/doi/10.1016/j.neucom.2025.130470 | H26: Preprint | I26: Preprint-Suchquelle | J26: ARXIV-01 | K26: Teilweise | L26: Include | N26: RQ2; RQ3; RQ4; RQ5; Gap; Methodik | O26: Nein | R26: - Relevantes B-Supporting-Include zu Reflection, Memory-Augmentation und self-evolving LLM-Agenten; kein A-Core-Webagentenpaper, aber mit AgentBench-, WebShop- und Mind2Web-Bezug. - Architektur: SAGE nutzt User-, Assistant- und Checker-Agenten, iterative Feedbackschleifen, Short-Term Memory, Long-Term Memory, Reflection und MemorySyntax auf Basis der Ebbinghaus-Vergessenskurve. - Validierung/Replanning: Checker bewertet Outputs und liefert Feedback; Reflection speichert Fehler-/Verbesserungshinweise, wodurch spätere Entscheidungen angepasst werden können, aber kein explizites Online-Replanning-Modul wie bei WebATLAS/WebOperator. - Evaluation auf AgentBench-Domänen wie OS, DB, KG, ALFWorld, WebShop und Mind2Web sowie HotpotQA, TriviaQA und Code-/Long-Context-Tasks; Forschungslücke: unklare Übertragbarkeit auf komplexe Browsersteuerung, begrenzte Analyse von Tokenkosten, Laufzeit, Replan-Anzahl und Validierungsintervallen.
A27: C026 | B27: S026 | C27: Instruction Tuning for Large Language Models: A Survey | D27: Zhang et al. (2026) | E27: 2026 | F27: ACM Computing Surveys | G27: https://doi.org/10.1145/3777411 | H27: Survey | I27: wissenschaftliche Datenbank | J27: ACM-01 | K27: Teilweise | L27: Exclude | M27: Zu allgemeiner Survey zu Instruction Tuning von LLMs; behandelt Prompting/Instruction Following nur indirekt und nicht als agentische Prompt-Engineering-Strategie für Webagenten, Planung, Replanning oder Validierung. | N27: Methodik | O27: Nein | R27: - Allgemeiner Survey zu Instruction Tuning, Instruction-Datasets, SFT, instruction-finetuned Models und Evaluation, aber ohne direkten Webagentenfokus. - Prompt Engineering ist für die SLR grundsätzlich relevant, dieses Paper behandelt jedoch primär Training auf Instruction-Output-Paaren und nicht ReAct-/Reflection-/Planning-Prompts in Agenten. - Keine konkrete Agentenarchitektur, keine Browserumgebung, keine Webnavigation, kein Replanning und keine Webagenten-spezifischen Effizienzmetriken. - Für deine Fragestellung durch spezifischere Agenten- und Webagentenquellen besser abgedeckt; daher nicht weiter extrahieren.
A28: C027 | B28: S027 | C28: Agent-Pro: Learning to Evolve via Policy-Level Reflection and Optimization | D28: Zhang et al. (2024) | E28: 2024 | F28: ACL 2024 / Proceedings of the 62nd Annual Meeting of the Association for Computational Linguistics (Long Papers) | G28: https://aclanthology.org/2024.acl-long.292/; https://github.com/zwq2018/Agent-Pro | H28: Conference Paper | I28: wissenschaftliche Datenbank | J28: ARXIV-01 | K28: Ja | L28: Include | N28: RQ1; RQ2; RQ3; RQ4; RQ5; Gap; Methodik | O28: Nein | R28: - Sehr relevantes A-/B+ Supporting-Include zu Long-Horizon-Agenten, Policy-Level Reflection, Belief-aware Decision-Making und Strategie-Evolution; keine direkte Webagentenstudie, aber stark auf Webagenten übertragbar. - Architektur: Agent-Pro nutzt Self-Belief und World-Belief für Entscheidungen sowie Behavioral Guidelines und World Modeling als optimierbare Policy-Bestandteile im Prompt. - Planung/Validierung/Replanning: reflektiert ganze Trajektorien, Beliefs und Endresultate statt einzelner Aktionen; prüft Korrektheit, Konsistenz und Rationalität von Beliefs und optimiert Policies über Verification und DFS-basierte Policy Evolution. - Evaluation auf Blackjack und Limit Texas Hold’em mit Win Rate, Chip Counts, Policy Payoff und Ablationen gegen Vanilla LLM, ReAct und Reflexion; Forschungslücke: keine Web-/Browserumgebung, Übertragbarkeit auf Webagenten, DOM-Aktionen, Tool-Feedback, Tokenkosten und Laufzeit bleibt offen.
A29: C028 | B29: S028 | C29: WebArena: A Realistic Web Environment for Building Autonomous Agents | D29: Zhou et al. (2024) | E29: 2024 | F29: ICLR 2024 | G29: arXiv:2307.13854; https://arxiv.org/abs/2307.13854; https://webarena.dev/ | H29: Conference Paper / Benchmark Paper | I29: wissenschaftliche Datenbank | J29: ARXIV-01 | K29: Ja | L29: Include | N29: RQ1; RQ2; RQ3; RQ4; RQ5; Gap; Methodik | O29: Nein | R29: - Zentrales A-Core-Include und Benchmark-Grundlagenpaper für LLM-basierte Webagenten, realistische Webumgebungen und Long-Horizon-Webtasks. - Methode/Umgebung: WebArena stellt self-hostbare Websites aus E-Commerce, Forum, GitLab/Softwareentwicklung und CMS bereit, ergänzt durch Tools wie Map, Calculator, Scratchpad und Knowledge Resources. - Planung/Validierung: Aufgaben sind high-level, mehrschrittig und funktional zu lösen; Evaluation prüft funktionale Korrektheit statt bloßer Aktionssequenz-Ähnlichkeit und umfasst auch unachievable tasks sowie Stop-/Failure-Verhalten. - Evaluation mit 812 Webtasks, End-to-End Task Success Rate und Human Baseline; GPT-4 erreicht nur 14,41 % gegenüber 78,24 % Human Performance; Forschungslücke: Bedarf an besserer Planung, Exploration, State Tracking, Failure Recovery, Replanning und Effizienzmetriken wie Tokenkosten/Laufzeit.
A30: C029 | B30: S029 | C30: Agentic Context Engineering: Evolving Contexts for Self-Improving Language Models | D30: Zhang et al. (2026) | E30: 2026 | F30: ICLR 2026 / arXiv | G30: arXiv:2510.04618v2; https://arxiv.org/abs/2510.04618; https://github.com/ace-agent/ace | H30: Conference Paper / Preprint | I30: Preprint-Suchquelle | J30: ARXIV-01 | K30: Ja | L30: Include | N30: RQ2; RQ3; RQ4; RQ5; Gap; Methodik | O30: Nein | R30: - Sehr relevantes B+/A-Supporting-Include zu agentischem Context Engineering, Memory, Reflection und Test-Time Adaptation; kein klassisches Webbrowser-Agentenpaper, aber stark relevant für selbstverbessernde Agenten. - Architektur: ACE nutzt Generator, Reflector und Curator, um aus Trajektorien, Execution Feedback und Fehlern strukturierte Context Playbooks mit Delta Context Items aufzubauen. - Validierung/Replanning: Reflector extrahiert Lessons aus Erfolgen und Fehlern; Curator integriert sie inkrementell, wodurch spätere Agentenausführungen besser gesteuert werden, ohne Modellgewichte zu ändern. - Evaluation auf AppWorld sowie Finanzbenchmarks mit Task Goal Completion, Scenario Goal Completion, Accuracy, Rollouts, Tokenkosten und Adaptation Latency; Forschungslücke: Übertragbarkeit auf echte Web-/Browseragenten, DOM-Aktionen, Replanning-Zeitpunkte und Feedbackqualität bleibt weiter zu prüfen.
A31: C030 | B31: S030 | C31: The Illusion of Diminishing Returns: Measuring Long Horizon Execution in LLMs | D31: Sinha et al. (2026) | E31: 2026 | F31: ICLR 2026 / arXiv | G31: arXiv:2509.09677v3; https://arxiv.org/abs/2509.09677 | H31: Conference Paper / Preprint | I31: Preprint-Suchquelle | J31: ARXIV-01 | K31: Teilweise | L31: Include | N31: RQ1; RQ3; RQ4; RQ5; Gap; Methodik | O31: Nein | R31: - Sehr relevantes A-/B+ Supporting-Include zu Long-Horizon Execution, Planungshorizonten und Fehlerfortpflanzung bei LLMs; keine direkte Webagentenstudie, aber stark übertragbar auf lange Webagenten-Trajektorien. - Methode: trennt Planning, Knowledge und Execution, indem Wissen und Plan explizit vorgegeben werden und nur die zuverlässige Ausführung über viele Schritte gemessen wird. - Validierung/Fehlermechanismus: zeigt Self-Conditioning, bei dem frühere Modellfehler im Kontext spätere Fehler wahrscheinlicher machen; Thinking/CoT kann diesen Effekt teilweise mindern und längere Ausführung ermöglichen. - Evaluation mit Step Accuracy, Turn Accuracy, Task Accuracy und Horizon Length; Forschungslücke: synthetisches Setting, keine direkte Browser-/DOM-Umgebung, aber sehr relevant für Metriken zu Long-Horizon-Webtasks, Fehlerpositionen, Recovery und Replanning.
A32: C031 | B32: S031 | C32: Measuring AI Ability to Complete Long Software Tasks | D32: Kwa et al. (2026) | E32: 2026 | F32: arXiv / METR Preprint | G32: arXiv:2503.14499v3; https://arxiv.org/abs/2503.14499 | H32: Preprint | I32: Preprint-Suchquelle | J32: ARXIV-01 | K32: Teilweise | L32: Include | N32: RQ1; RQ3; RQ4; RQ5; Gap; Methodik | O32: Nein | R32: - Sehr relevantes A-Supporting-Include als zentrale Methodikquelle für Long-Horizon-Evaluation, Taskdauer und agentische Zuverlässigkeit; keine direkte Webagentenstudie, aber stark übertragbar auf lange Webagenten-Tasks. - Methode: führt den Task Completion Time Horizon ein, insbesondere den 50 %-Time-Horizon als menschliche Bearbeitungszeit von Aufgaben, die KI-Agenten mit 50 % Erfolgswahrscheinlichkeit lösen. - Evaluation/Validierung: kombiniert HCAST, RE-Bench und SWAA mit Human Baselines, Agent Success Rates, logistischer Modellierung und qualitativer Fehleranalyse zu Planung/Tool Choice, Premature Abandonment und Repeating Failed Actions. - Forschungslücke: Webagenten-Benchmarks sollten nicht nur Success Rate, sondern auch Aufgabenlänge, menschliche Zeitäquivalente, Zuverlässigkeit bei längeren Tasks, Recovery-Fähigkeit und externe Validität messen.
A33: C032 | B33: S032 | C33: In-context Learning and Induction Heads | D33: Olsson et al. (2022) | E33: 2022 | F33: Transformer Circuits Thread / Anthropic | G33: https://transformer-circuits.pub/2022/in-context-learning-and-induction-heads/ | H33: Research Article / Technical Report | I33: Datenbank | J33: ARXIV-03 | K33: Teilweise | L33: Background | N33: RQ1; RQ3; Gap; Methodik | O33: Nein | R33: - Wichtige Background-Quelle zum mechanistischen Verständnis von In-Context Learning in Transformer-Modellen; keine direkte Webagentenstudie. - Methode/Beitrag: untersucht Induction Heads als mögliche Mechanismen, mit denen Transformer Muster im Kontext erkennen und fortsetzen können. - Relevanz indirekt für Agenten: erklärt, warum Prompting, Few-shot-Beispiele, Kontextverläufe und Memory-ähnliche Informationen Agentenverhalten beeinflussen können. - Keine direkte Behandlung von Webnavigation, Agentenarchitekturen, Planning, Replanning oder Webagenten-Evaluationsmetriken; daher nur als theoretischer Hintergrund nutzen.
A34: C033 | B34: S033 | C34: The Illusion of Thinking: Understanding the Strengths and Limitations of Reasoning Models via the Lens of Problem Complexity | D34: Shojaee et al. (2025) | E34: 2025 | F34: arXiv / Apple | G34: arXiv:2506.06941v3; https://arxiv.org/abs/2506.06941 | H34: Preprint | I34: Preprint-Suchquelle | J34: ARXIV-03 | K34: Teilweise | L34: Include | N34: RQ3; RQ4; RQ5; Gap; Methodik | O34: Nein | R34: - Relevantes B-Supporting-Include zu Grenzen von Large Reasoning Models, Chain-of-Thought/Thinking, Planning-Komplexität und Reasoning Collapse; keine direkte Webagentenstudie. - Methode: kontrollierbare Puzzle-Umgebungen wie Tower of Hanoi, Checker Jumping, River Crossing und Blocks World erlauben systematische Variation von Problemkomplexität und Analyse von Reasoning Traces. - Validierung/Fehleranalyse: zeigt Overthinking bei einfachen Aufgaben, spätes Finden korrekter Lösungen bei mittlerer Komplexität und Accuracy Collapse mit Fixierung auf frühe Fehler bei hoher Komplexität; explizite Algorithmen verbessern die Ausführung kaum. - Evaluation mit Accuracy, Pass@k, Inference Compute Budget, Thinking Tokens und Position korrekter/inkorrekter Lösungen im Thought Trace; Forschungslücke: Übertragbarkeit auf Webagenten, Browseraktionen, DOM-Zustände, Recovery und echtes Replanning bleibt offen.
A35: C034 | B35: S034 | C35: Chain of Thoughtlessness? An Analysis of CoT in Planning | D35: Stechly et al. (2025) | E35: 2025 | F35: NeurIPS 2024 / arXiv | G35: arXiv:2405.04776v3; https://arxiv.org/abs/2405.04776 | H35: Conference Paper / Preprint | I35: Preprint-Suchquelle | J35: ARXIV-01 | K35: Teilweise | L35: Background | N35: RQ3; RQ4; Gap; Methodik | O35: Nein | R35: - Relevante Background-Quelle zu Chain-of-Thought und Grenzen von CoT bei Planning-Aufgaben; keine direkte Webagentenstudie. - Methode: untersucht CoT-Prompting in Blocksworld sowie skalierbaren Varianten von CoinFlip, LastLetterConcatenation und mehrstufiger Arithmetik. - Relevanz für Planung: zeigt, dass CoT-Verbesserungen stark von sehr spezifischen Prompts abhängen und bei größeren bzw. leicht veränderten Instanzen schnell einbrechen. - Forschungslücke: CoT allein reicht nicht für robuste Long-Horizon-Planung, Validierung oder Replanning; Webagenten benötigen zusätzliche Mechanismen wie State Tracking, Tool-Feedback und explizite Fehlerprüfung.
A36: C035 | B36: S035 | C36: How Language Model Hallucinations Can Snowball | D36: Zhang et al. (2023) | E36: 2023 | F36: arXiv | G36: arXiv:2305.13534v1; https://arxiv.org/abs/2305.13534 | H36: Preprint | I36: Preprint-Suchquelle | J36: ACM-03 | K36: Teilweise | L36: Include | N36: RQ3; RQ4; RQ5; Gap; Methodik | O36: Nein | R36: - Relevantes B-Supporting-Include zu Fehlerfortpflanzung, Hallucination Snowballing und Konsistenzdruck in Sprachmodellen; keine direkte Webagentenstudie, aber stark auf Long-Horizon-Agenten übertragbar. - Methode: konstruiert QA-Datasets zu Primality Testing, Senator Search und Graph Connectivity, bei denen Modelle früh eine Antwort committen und anschließend falsche Begründungen erzeugen können. - Validierung/Fehlermechanismus: zeigt, dass Modelle viele eigene falsche Folgebehauptungen isoliert erkennen können, sie aber im Kontext einer vorherigen falschen Antwort dennoch erzeugen; relevant für Zwischenprüfung, Backtracking und Replanning. - Evaluation mit Error Rate, Snowballed Hallucination Rate und separaten Verification Questions; Forschungslücke: Übertragung auf Webagenten, DOM-Zustände, Tool-Feedback, Aktionsfehler und prozessbezogene Recovery-Metriken bleibt offen.
A37: C036 | B37: S036 | C37: Generalizable Long-Horizon Manipulations with Large Language Models | D37: Zhou et al. (2023) | E37: 2023 | F37: arXiv | G37: arXiv:2310.02264v1; https://arxiv.org/abs/2310.02264; https://object814.github.io/Task-Condition-With-LLM/ | H37: Preprint | I37: Preprint-Suchquelle | J37: ARXIV-01 | K37: Ja | L37: Include | N37: RQ2; RQ3; RQ4; RQ5; Gap; Methodik | O37: Nein | R37: - Relevantes B-Supporting-Include aus der Robotik zu Long-Horizon-Manipulation, Task Conditions und strukturierter Ausführung; keine direkte Webagentenstudie, aber methodisch gut übertragbar. - Architektur: LLM generiert und generalisiert primitive Task Conditions mit relevanten Objekten, Pre-conditions, Post-conditions und erlaubten Kollisionen; DMPs erzeugen Low-Level-Trajektorien. - Planung/Validierung/Replanning: rekursive Precondition Satisfaction erzeugt notwendige Zwischentasks; während der Ausführung werden Umweltzustände und Kollisionen geprüft und Trajektorien bei unerwünschten Kollisionen angepasst. - Evaluation in PyBullet und Real-World-Setup mit Success Rates für primitive Tasks, Long-Horizon Tasks sowie Generalisierung auf neue Objekte und neue primitive Tasks; Forschungslücke: domänenspezifisch für Robotik, keine Web-/DOM-Umgebung, keine Tokenkosten/Laufzeit und keine Webagenten-spezifischen Recovery-Metriken.
